Workbook

Sheet TOTALES
B1: CANTIDAD | C1: VALOR | D1: COSTO | E1: CATEGORIA | F1: ESTADO | G1: CAJA | H1: CATEGORIA | I1: UNIDADES | J1: VALOR | K1: PROMEDIO VALOR
A2: 499 | B2: =SUM(#REF!) -> #REF! | C2: 28.8 | D2: =B2*C2 -> #REF! | E2: FUNDA | F2: A | G2: SI | H2: MICAS | I2: =SUMIF(E:E,"*MICA*",B:B) -> 45808 | J2: =SUMIF(E:E,"*MICA*",D:D) -> 726259.4 | K2: =J2/I2 -> 15.854423
A3: 678 | B3: =SUM('678'!B:B) -> 9054 | C3: 19.7 | D3: =B3*C3 -> 178363.8 | E3: FUNDA | F3: A | G3: SI | H3: TABLETA | I3: =SUMIF(E:E,"*TABLETA*",B:B) -> 30716 | J3: =SUMIF(E:E,"*TABLETA*",D:D) -> 2654439.3 | K3: =J3/I3 -> 86.418782
A4: 380 | B4: =SUM('380'!B:B) -> 660 | C4: 102.5 | D4: =B4*C4 -> 67650 | E4: TABLETA | F4: A | G4: NO | H4: FUNDAS | I4: =SUMIF(E:E,"*FUNDA*",B:B) -> #REF! | J4: =SUMIF(E:E,"*FUNDA*",D:D) -> #REF! | K4: =J4/I4 -> #REF!
A5: 662 | B5: =SUM('662'!B:B) -> 5046 | C5: 12 | D5: =B5*C5 -> 60552 | E5: FUNDA | F5: A | G5: SI | H5: VIENE EN CAJA | I5: =SUMIF(G:G,"*SI*",B:B) -> #REF!
A6: 514 | B6: =SUM('514'!B:B) -> 4239 | C6: 16.1 | D6: =B6*C6 -> 68247.9 | E6: FUNDA | F6: A | G6: SI | H6: ESTADO | I6: UNIDADES | J6: VALOR
A7: 412 | B7: =SUM('412'!B:B) -> 1875 | C7: 50.9 | D7: =B7*C7 -> 95437.5 | E7: TABLETA | F7: A | G7: NO | H7: A | I7: =SUMIF(F:F,"*A*",B:B) -> #REF! | J7: =SUMIF(F:F,"*A*",D:D) -> #REF!
A8: 437 | B8: =SUM('437'!B:B) -> 8081 | C8: 80 | D8: =B8*C8 -> 646480 | E8: TABLETA | F8: A | G8: NO | H8: B | I8: =SUMIF(F:F,"*B*",B:B) -> 5441 | J8: =SUMIF(F:F,"*B*",D:D) -> 136494.9
A9: 367 | B9: =SUM('367'!B:B) -> 3600 | C9: 17.5 | D9: =B9*C9 -> 63000 | E9: FUNDA | F9: B | G9: NO | H9: C | I9: =SUMIF(F:F,"*C*",B:B) -> 38500 | J9: =SUMIF(F:F,"*C*",D:D) -> 862484.3
A10: 730 | B10: =SUM('730'!B:B) -> 2885 | C10: 20.3 | D10: =B10*C10 -> 58565.5 | E10: FUNDA | F10: C | G10: SI
A11: 648 | B11: =SUM('648'!B:B) -> 2648 | C11: 18.6 | D11: =B11*C11 -> 49252.8 | E11: FUNDA | F11: A | G11: SI | H11: ESTADO | I11: MICAS UNIDADES | J11: TABLETAS UNIDADES | K11: FUNDAS UNIDADES
A12: 456 | B12: =SUM('456'!B:B) -> 947 | C12: 16.5 | D12: =B12*C12 -> 15625.5 | E12: MICA | F12: B | G12: SI | H12: A | I12: =SUMIFS(B:B, E:E, "MICA",F:F, "A") -> 42591 | J12: =SUMIFS(B:B, E:E, "TABLETA",F:F, "A") -> 30052 | K12: =SUMIFS(B:B, E:E, "FUNDA",F:F, "A") -> #REF!
A13: 462 | B13: =SUM('462'!B:B) -> 7770 | C13: 9.7 | D13: =B13*C13 -> 75369 | E13: MICA | F13: A | G13: SI | H13: B | I13: =SUMIFS(B:B, E:E, "MICA",F:F, "B") -> 1317 | J13: =SUMIFS(B:B, E:E, "TABLETA",F:F, "B") -> 524 | K13: =SUMIFS(B:B, E:E, "FUNDA",F:F, "B") -> 3600
A14: 728 | B14: =SUM('728'!B:B) -> 2488 | C14: 21.8 | D14: =B14*C14 -> 54238.4 | E14: FUNDA | F14: A | G14: SI | H14: C | I14: =SUMIFS(B:B, E:E, "MICA",F:F, "C") -> 1900 | J14: =SUMIFS(B:B, E:E, "TABLETA",F:F, "C") -> 140 | K14: =SUMIFS(B:B, E:E, "FUNDA",F:F, "C") -> 36460
A15: 491 | B15: =SUM('491'!B:B) -> 4389 | C15: 16.5 | D15: =B15*C15 -> 72418.5 | E15: MICA | F15: A | G15: SI
A16: 498 | B16: =SUM('498'!B:B) -> 1191 | C16: 13 | D16: =B16*C16 -> 15483 | E16: MICA | F16: A | G16: SI
A17: 576 | B17: =SUM('576'!B:B) -> 2267 | C17: 21.2 | D17: =B17*C17 -> 48060.4 | E17: FUNDA | F17: C | G17: SI | H17: ESTADO | I17: MICAS VALOR | J17: TABLETAS VALOR | K17: FUNDAS VALOR
A18: 621 | B18: =SUM('621'!B:B) -> 2144 | C18: 21.6 | D18: =B18*C18 -> 46310.4 | E18: FUNDA | F18: C | G18: NO | H18: A | I18: =SUMIFS(D:D, E:E, "MICA",F:F, "A") -> 687726.5 | J18: =SUMIFS(D:D, E:E, "TABLETA",F:F, "A") -> 2585660.9 | K18: =SUMIFS(D:D, E:E, "FUNDA",F:F, "A") -> #REF!
A19: 540 | B19: =SUM('540'!B:B) -> 1511 | C19: 89 | D19: =B19*C19 -> 134479 | E19: TABLETA | F19: A | G19: NO | H19: B | I19: =SUMIFS(D:D, E:E, "MICA",F:F, "B") -> 19732.5 | J19: =SUMIFS(D:D, E:E, "TABLETA",F:F, "B") -> 53762.4 | K19: =SUMIFS(D:D, E:E, "FUNDA",F:F, "B") -> 63000
A20: 439 | B20: =SUM('439'!B:B) -> 1945 | C20: 18.2 | D20: =B20*C20 -> 35399 | E20: FUNDA | F20: C | G20: NO | H20: C | I20: =SUMIFS(D:D, E:E, "MICA",F:F, "C") -> 18800.4 | J20: =SUMIFS(D:D, E:E, "TABLETA",F:F, "C") -> 15016 | K20: =SUMIFS(D:D, E:E, "FUNDA",F:F, "C") -> 828667.9
A21: 584 | B21: =SUM('584'!B:B) -> 1931 | C21: 20.5 | D21: =B21*C21 -> 39585.5 | E21: FUNDA | F21: C | G21: SI
A22: 722 | B22: =SUM('722'!B:B) -> 1800 | C22: 21.7 | D22: =B22*C22 -> 39060 | E22: FUNDA | F22: C | G22: NO
A23: 578 | B23: =SUM('578'!B:B) -> 50 | C23: 98 | D23: =B23*C23 -> 4900 | E23: TABLETA | F23: C | G23: NO
A24: 450 | B24: =SUM('450'!B:B) -> 1726 | C24: 15.8 | D24: =B24*C24 -> 27270.8 | E24: FUNDA | F24: C | G24: NO
A25: 735 | B25: =SUM('735'!B:B) -> 1769 | C25: 23.2 | D25: =B25*C25 -> 41040.8 | E25: FUNDA | F25: C | G25: NO
A26: 594 | B26: =SUM('594'!B:B) -> 1427 | C26: 8.7 | D26: =B26*C26 -> 12414.9 | E26: MICA | F26: C | G26: NO
A27: 598 | B27: =SUM('598'!B:B) -> 1491 | C27: 21 | D27: =B27*C27 -> 31311 | E27: MICA | F27: A | G27: NO
A28: 599 | B28: =SUM('599'!B:B) -> 1450 | C28: 123.6 | D28: =B28*C28 -> 179220 | E28: TABLETA | F28: A | G28: NO
A29: 601 | B29: =SUM('601'!B:B) -> 18005 | C29: 19 | D29: =B29*C29 -> 342095 | E29: MICA | F29: A | G29: NO
A30: 602 | B30: =SUM('602'!B:B) -> 524 | C30: 102.6 | D30: =B30*C30 -> 53762.4 | E30: TABLETA | F30: B | G30: NO
A31: 603 | B31: =SUM('603'!B:B) -> 3624 | C31: 99.5 | D31: =B31*C31 -> 360588 | E31: TABLETA | F31: A | G31: NO
A32: 582 | B32: =SUM('582'!B:B) -> 1638 | C32: 19.6 | D32: =B32*C32 -> 32104.8 | E32: FUNDA | F32: C | G32: SI
A33: 644 | B33: =SUM('644'!B:B) -> 1529 | C33: 24 | D33: =B33*C33 -> 36696 | E33: FUNDA | F33: A | G33: SI
A34: 669 | B34: =SUM('669'!B:B) -> 1500 | C34: 31.6 | D34: =B34*C34 -> 47400 | E34: FUNDA | F34: C | G34: NO
A35: 613 | B35: =SUM('613'!B:B) -> 4113 | C35: 94.7 | D35: =B35*C35 -> 389501.1 | E35: TABLETA | F35: A | G35: NO
A36: 388 | B36: =SUM('388'!B:B) -> 1306 | C36: 17.5 | D36: =B36*C36 -> 22855 | E36: FUNDA | F36: C | G36: NO
A37: 617 | B37: =SUM('617'!B:B) -> 90 | C37: 112.4 | D37: =B37*C37 -> 10116 | E37: TABLETA | F37: C | G37: NO
A38: 620 | B38: =SUM('620'!B:B) -> 660 | C38: 19.3 | D38: =B38*C38 -> 12738 | E38: MICA | F38: A | G38: NO
A39: 676 | B39: =SUM('676'!B:B) -> 1010 | C39: 17.3 | D39: =B39*C39 -> 17473 | E39: FUNDA | F39: C | G39: NO
A40: 714 | B40: =SUM('714'!B:B) -> 978 | C40: 17.2 | D40: =B40*C40 -> 16821.6 | E40: FUNDA | F40: A | G40: NO
...

Sheet 362
A9: 362-Rmn13-5G-blue | B9: 23
A10: 362-Rmn13-5G-blk | B10: 50
A14: 362-Rmn13pro-4G-blue | B14: 35

Sheet 367
A1: 367-A05 | B1: 360
A2: 367-A05s | B2: 10
A4: 367-A14 | B4: 20
A5: 367-A15 | B5: 40
A6: 367-A24-4G | B6: 20
A8: 367-A36 | B8: 70
A9: 367-A56 | B9: 900
A10: 367-S22 | B10: 30
A11: 367-S22plus | B11: 60
A12: 367-S22ultra | B12: 30
A13: 367-S23 | B13: 10
A14: 367-S24 | B14: 40
... A37: C-367-Rm14/C75 | B37: 320

Sheet CONSECUTIVO TOTALES
A1: MODELO | B1: CANTIDAD | C1: VALOR | D1: COSTO | E1: CATEGORIA | F1: 29 AGOSTO
A2: 314A | B2: 6672 | C2: 7.76 | D2: 51774.72 | E2: FUNDA
A3: 314 GLASS | B3: 5481 | C3: 13.16 | D3: 72129.96 | E3: FUNDA
A4: 325 | B4: 78 | C4: 18 | D4: 1404 | E4: FUNDA
A5: 329 | B5: 55 | C5: 17.5 | D5: 962.5 | E5: FUNDA
A6: 333A | B6: 15236 | C6: 18.2 | D6: 277295.2 | E6: FUNDA
A7: 336 | B7: 1837 | C7: 18.33 | D7: 33672.21 | E7: FUNDA
A8: 340 | B8: 223 | C8: 14.75 | D8: 3289.25 | E8: FUNDA
A9: 362 | B9: 21071 | C9: 25 | D9: 526775 | E9: FUNDA
A10: 367 | B10: 15630 | C10: 19 | D10: 296970 | E10: FUNDA
A11: 373 | B11: 49 | C11: 22.45 | D11: 1100.05 | E11: FUNDA
A12: 374 | B12: 531 | C12: 19.05 | D12: 10115.55 | E12: FUNDA
A13: 376 | B13: 721 | C13: 16.25 | D13: 11716.25 | E13: FUNDA
A14: 380 | B14: 1625 | C14: 105 | D14: 170625 | E14: TABLETA
A15: 388 | B15: 1800 | C15: 13.76 | D15: 24768 | E15: FUNDA
A16: 388 BICOLOR | B16: 228 | C16: 17.6 | D16: 4012.8 | E16: FUNDA
A17: 389 | B17: 1844 | C17: 21.24 | D17: 39166.56 | E17: FUNDA
A18: 393 | B18: 81 | C18: 22.75 | D18: 1842.75 | E18: FUNDA
A19: 394 | B19: 1506 | C19: 21.91 | D19: 32996.46 | E19: FUNDA
A20: 395 | B20: 400 | C20: 20.41 | D20: 8164 | E20: FUNDA
A21: 398 | B21: 6502 | C21: 18.31 | D21: 119051.62 | E21: FUNDA
A22: 407 | B22: 473 | C22: 16.61 | D22: 7856.53 | E22: FUNDA
A23: 412 | B23: 2646 | C23: 50.25 | D23: 132961.5 | E23: TABLETA
A24: 421 | B24: 222 | C24: 25.25 | D24: 5605.5 | E24: FUNDA
A25: 427 | B25: 349 | C25: 61.25 | D25: 21376.25 | E25: TABLETA
A26: 430 | B26: 1087 | C26: 27.7 | D26: 30109.9 | E26: FUNDA
A27: 432 | B27: 256 | C27: 13.5 | D27: 3456 | E27: FUNDA
A28: 437 | B28: 3503 | C28: 96.25 | D28: 337163.75 | E28: TABLETA
... A84: 14033 | B84: 277 | C84: 88.25 | D84: 24445.25 | E84: TABLETA
A85: TOTAL | B85: 181039 | D85: 4494873.6
A89: MODELO | B89: CANTIDAD | C89: VALOR | D89: COSTO | E89: CATEGORIA | F89: 45209
A90: 314A | B90: 8981 | C90: 7.76 | D90: 69692.56 | E90: FUNDA
A91: 314 GLASS | B91: 5346 | C91: 13.16 | D91: 70353.36 | E91: FUNDA
A92: 325 | B92: 28 | C92: 18 | D92: 504 | E92: FUNDA
A93: 329 | B93: 55 | C93: 17.5 | D93: 962.5 | E93: FUNDA
A94: 333A | B94: 18177 | C94: 18.2 | D94: 330821.4 | E94: FUNDA
A95: 336 | B95: 0 | C95: 18.33 | D95: 0 | E95: FUNDA
A96: 340 | B96: 213 | C96: 14.75 | D96: 3141.75 | E96: FUNDA
A97: 362 | B97: 20276 | C97: 25 | D97: 506900 | E97: FUNDA
A98: 367 | B98: 15559 | C98: 19 | D98: 295621 | E98: FUNDA
...

Sheet 380
A1: 380-A11-blk | B1: 30
A2: 380-A11-navy | B2: 135
A3: 380-A11-pink | B3: 100
A4: 380-A11-red | B4: 95
A6: 380-A11plus-navy | B6: 95
A9: 380-A9plus-blk | B9: 120
A11: 380-A9-red | B11: 65
A12: 380-A9-pink | B12: 20

Sheet 388
A1: SKU
A2: 388-A04s | B2: 70
A3: 388-A15 | B3: 80
A4: 388-A17 | B4: 200
A5: 388-A26 | B5: 50
A6: 388-A32 | B6: 70
A8: 388-A52 | B8: 90
A9: 388-A53 | B9: 16
A11: 388-S21 | B11: 10
A12: 388-S22plus | B12: 10
A13: 388-S22ultra | B13: 30
A15: 388-S23plus | B15: 100
A19: 388-S24plus | B19: 130
... A23: 388-S25plus | B23: 100

Sheet 398
A1: 398-A05-blk | B1: 30
A2: 398-A06-blk | B2: 80
A3: 398-A14-red | B3: 42
A5: 398-A25-5G-blk | B5: 60
A6: 398-A25-5G-pink | B6: 40
A7: 398-A25-5G-red | B7: 40
A8: 398-A33-red | B8: 30
A10: 398-S24-red | B10: 15
A11: 398-S25-blk | B11: 61
A12: 398-S25-pink | B12: 91
A13: 398-S25-red | B13: 80
A14: 398-S25plus-blk | B14: 50
... A28: 398-i16promax-blk | B28: 63

Sheet 412
A1: 412-iPad10-blue | B1: 15
A3: 412-A11-blk | B3: 630
A4: 412-A11-navy | B4: 170
A5: 412-A11-mint | B5: 190
A6: 412-A11-purple | B6: 190
A7: 412-A11-pink | B7: 360
A8: 412-A11-grey | B8: 180
A10: 412-A11plus-blk | B10: 60
A13: 412-A11plus-pink | B13: 80

Sheet 437
A1: 437-iPadPro11-2024-purple | B1: 10
A3: 437-A11-blk | B3: 1710
A4: 437-A11-purple | B4: 595
A5: 437-A11-navy | B5: 810
A6: 437-A11-magenta | B6: 660
A7: 437-A11-pink | B7: 435
A8: 437-A11-red | B8: 145
A11: 437-A11plus-blk | B11: 555 | C11: mandar a amzon se vende bien y mas caro
A12: 437-A11plus-pink | B12: 231 | C12: mandar a amzon se vende bien y mas caro
A13: 437-A11plus-purple | B13: 474 | C13: mandar a amzon se vende bien y mas caro
A14: 437-A11plus-navy | B14: 84
A15: 437-A11plus-red | B15: 50
A16: 437-A11plus-magenta | B16: 404
A18: 437-ipad10-blk | B18: 611
A20: 437-ipad10-purple | B20: 415
A22: 437-A9plus-blk | B22: 324
A23: 437-A9plus-blue | B23: 83
A24: 437-A9plus-red | B24: 42
A25: 437-A9plus-purple | B25: 17
A26: 437-A9plus-mint | B26: 26
A27: 437-A9-blk | B27: 110
A29: 437-A9-blue | B29: 30
... A35: 437-RmPad-2-red | B35: 30

Sheet 439
A1: 439-A04s-purple | B1: 9
A2: 439-A24-4G-blue | B2: 60
A3: 439-A25-blue | B3: 22
A4: 439-A26-purple | B4: 10
A5: 439-A34-blue | B5: 81
A6: 439-A34-transparent | B6: 50
A7: 439-S23fe-purple | B7: 10
A8: 439-S24-blue | B8: 13
A9: 439-S24-pink | B9: 4
A10: 439-S25-pink | B10: 40
A11: 439-S25-purple | B11: 20
A12: 439-S25-transparent | B12: 40
... A54: 439-Rmn13pro-5G-transparent | B54: 10

Sheet 448
A1: 448-i14-purple | B1: 18
A3: 448-i15-purple | B3: 24
A7: 448-i15pro-blk | B7: 10
A9: 448-i15pro-pink | B9: 20
A14: 448-i16pro-blue | B14: 20
A15: 448-i16pro-pink | B15: 10
A16: 448-i16pro-purple | B16: 10
A18: 448-i16plus-purple | B18: 10
A20: 448-i16promax-purple | B20: 10

Sheet 450
A1: 450-Rmn10 | B1: 40
A4: 450-Rmn12 | B4: 10
A5: 450-Rmn12pro | B5: 28
A6: 450-Rmn13-4G | B6: 10
A7: 450-Rmn13-5G | B7: 20
A8: 450-Rmn13pro-4G | B8: 10
A9: 450-Rmn13pro-5G | B9: 20
A10: 450-RmA5 | B10: 40
A11: 450-Rm15c/C85 | B11: 110
A12: 450-Rmn14s | B12: 100
A14: 450-PocoM6pro | B14: 6
A15: 450-PocoM6plus | B15: 64
... A41: 450-S26ultra | B41: 60
A43: 450-i14pro
A44: 450-15pro | B44: 20
A45: 450-i16pro | B45: 11
A46: 450-i16e | B46: 40
A48: 450-G04 | B48: 10
A49: 450-G05 | B49: 10
A50: 450-G24power | B50: 137
A52: 450-G35 | B52: 40
A53: 450-G53
A54: 450-G55 | B54: 10
A55: 450-G56 | B55: 30
A58: 450-G86-transparent | B58: 30
A59: 450-E13
A60: 450-E15 | B60: 40

Sheet 456
A1: 456-ix | B1: 10
A5: 456-i11promax | B5: 72
A6: 456-i12promax | B6: 10
A11: 456-iAir | B11: 70
A13: 456-Rm12c | B13: 10
A15: 456-Rm14c | B15: 60
A18: 456-A05 | B18: 70
A19: 456-A06 | B19: 51
A20: 456-A17 | B20: 30
A21: 456-A25-5G | B21: 221
A22: 456-A26 | B22: 17 | C22: REETIQUETAR VIENE MAL
A23: 456-A34 | B23: 90
A24: 456-A35 | B24: 84
A25: 456-A36 | B25: 90
A27: 456-S25plus | B27: 13
A29: 456-E14 | B29: 40
A30: 456-G04 | B30: 9

Sheet 462
A1: N-462-A06 | B1: 114
A2: N-462-A14 | B2: 30
A4: N-462-A16 | B4: 60
A5: N-462-A17 | B5: 210
A6: N-462-A26 | B6: 84
A7: N-462-A32 | B7: 40
A8: N-462-A35 | B8: 50
A9: N-462-A36 | B9: 260
A10: N-462-A52 | B10: 50
A13: N-462-S22ultra | B13: 40
A16: N-462-S24 | B16: 60
A17: N-462-S24plus | B17: 30
... A68: N-462-Rm15c/C85 | B68: 80

Sheet 474
A1: 474-i14pro-blue | B1: 33
A2: 474-i15plus-blue | B2: 31
A3: 474-i15plus-mint | B3: 16
A4: 474-i15pro-blk | B4: 50
A5: 474-i15pro-purple | B5: 50
A7: 474-i16plus-blk | B7: 24
A8: 474-i16plus-blue | B8: 25
A9: 474-i16plus-purple | B9: 50
A10: 474-i16pro-blk | B10: 83
A11: 474-i16pro-blue | B11: 12
A12: 474-i16pro-pink | B12: 29
A13: 474-i16pro-purple | B13: 75
... A21: 474-i17promax-purple | B21: 10

Sheet 491
A2: 491-A05s | B2: 150
A3: 491-A06 | B3: 26
A4: 491-A07 | B4: 60
A5: 491-A14 | B5: 473
A6: 491-A15 | B6: 115
A7: 491-A16 | B7: 217
A8: 491-A17 | B8: 100
A9: 491-A23 | B9: 30
A10: 491-A25 | B10: 310
A11: 491-A26 | B11: 220
A12: 491-A33 | B12: 130
A13: 491-A36 | B13: 150
... A38: 491-Rm14c | B38: 275

Sheet 498
B1: 68
A2: 498-A05s | B2: 43
A3: 498-A06 | B3: 50
A5: 498-A16 | B5: 117
A6: 498-A17 | B6: 60
A7: 498-A25 | B7: 83
A8: 498-A34 | B8: 11
A11: 498-A52 | B11: 10
A12: 498-A57 | B12: 30
A14: 498-S26plus | B14: 20
A16: 498-G17 | B16: 70
A17: 498-G24 | B17: 38
A18: 498-G24power | B18: 110
... A34: 498-Rmn12 | B34: 10

Sheet 499
A1: 499-ise2022
A2: 499-ixr | B2: 100
A3: 499-i11 | B3: 1430
A4: 499-i11pro | B4: 162
A5: 499-i11promax | B5: 100
A6: 499-i12 | B6: 968
A7: 499-i13 | B7: 2061
A14: 499-i16e | B14: 187
A15: 499-i16pro | B15: 290
A16: 499-i16promax | B16: 1012
A18: 499-i17e | B18: 550
A19: 499-i17pro | B19: 2169
A21: 499-iAir | B21: 1335

Sheet 514
A1: 514-A03s | B1: 80
A2: 514-A04 | B2: 59
A3: 514-A04s | B3: 70
A4: 514-A05 | B4: 50
A5: 514-A05s | B5: 20
A6: 514-A06 | B6: 150
A7: 514-A07 | B7: 110
A9: 514-A14 | B9: 100
A10: 514-A15 | B10: 50
A11: 514-A16 | B11: 150
A12: 514-A17 | B12: 160
A13: 514-A25-5g | B13: 30
... A55: C-514-Rmn14s | B55: 50

Sheet 540
A2: 540-A11-purple | B2: 131
A3: 540-A11-navy | B3: 248
A4: 540-A11-pink | B4: 277
A5: 540-A11-red | B5: 20
A8: 540-A9plus-blk | B8: 64
A10: 540-iPad10-blk | B10: 50
A11: 540-iPad10-purple | B11: 100
A12: 540-iPad10-red | B12: 180
A14: 540-iPad10-pink | B14: 140
A17: 540-A11plus-purple | B17: 120
A19: 540-A11plus-pink | B19: 181

Sheet 545
A4: 545-i15pro-blk | B4: 10
A6: 545-i16pro-blk | B6: 50
A7: 545-i16pro-purple | B7: 20
A8: 545-i16pro-pink | B8: 20
A10: 545-i16plus-blue | B10: 10

Sheet 567
A1: 567-i11-transparent | B1: 49
A2: 567-i11-purple | B2: 10
A5: 567-i11pro-transparent
A6: 567-i12pro-purple | B6: 14
A7: 567-i12promax-purple | B7: 12
A10: 567-i16-blk | B10: 9
A13: 567-i16pro-blk | B13: 75
A14: 567-i16pro-purple | B14: 21
A15: 567-i16pro-transparent | B15: 50
A16: 567-i16promax-purple | B16: 68
A17: 567-i17pro-blk | B17: 20
A18: 567-i17pro-purple | B18: 30
A21: 567-iAir-blk | B21: 30
A22: 567-iAir-transparent | B22: 40
A23: 567-iAir-purple | B23: 20

Sheet 576
A1: 576-A04s-purple | B1: 8
A2: 576-A05-blk | B2: 10
A3: 576-A05s-blk | B3: 17
A4: 576-A06-blk | B4: 20
A5: 576-A07-blk | B5: 150
A6: 576-A07-mint | B6: 70
A7: 576-A07-purple | B7: 30
A8: 576-A15-mint | B8: 40
A9: 576-A15-purple | B9: 30
A11: 576-A16-mint | B11: 76
A12: 576-A16-purple | B12: 20
A13: 576-A17-blk | B13: 130
... A52: 576-S26ultra-mint | B52: 24

Sheet 578
A1: 578-A9 | B1: 50 | C1: MANDAR MELI TAMBIEN?

Sheet 582
A1: 582-A06-blk | B1: 20
A2: 582-A06-blue | B2: 20
A3: 582-A06-fuchsia | B3: 10
A4: 582-A06-purple | B4: 20
A5: 582-A07-fuchsia | B5: 10
A7: 582-A16-fuchsia | B7: 50
A8: 582-A16-purple | B8: 20
A9: 582-A25-blk | B9: 30
A10: 582-A25-blue | B10: 35
A11: 582-A25-fuchsia | B11: 32
A12: 582-A25-purple | B12: 31
A13: 582-A26-blue | B13: 5
... A78: 582-Rm13-blk | B78: 10

Sheet 584
A1: 584-A15-blk | B1: 5
A2: 584-A25-blk | B2: 31
A4: 584-A25-red | B4: 30
A6: 584-A26-blk | B6: 37
A7: 584-A35-blk | B7: 60
A8: 584-A35-blue | B8: 20
A9: 584-A35-red | B9: 22
A11: 584-A37-blk | B11: 50
A12: 584-A37-blue | B12: 40
A13: 584-A37-red | B13: 40
A14: 584-A55-blk | B14: 30
A15: 584-A55-red | B15: 49
... A80: 584-Rmn14pro-4G-blk | B80: 10

Sheet 594
A1: 594-ixr | B1: 20
A2: 594-i11promax | B2: 10
A7: 594-i16 | B7: 70
A8: 594-i16pro | B8: 59
A9: 594-I16plus | B9: 110
A10: 594-i16promax | B10: 79
A11: 594-i16e | B11: 130
A12: 594-i17 | B12: 80
A13: 594-i17pro | B13: 90
A15: 594-iAir | B15: 50
A17: 594-Rmn13-4G | B17: 40
A18: 594-Rmn13-5G | B18: 10
... A48: 594-S26ultra | B48: 39

Sheet 598
A1: 598-A17 | B1: 130
A2: 598-A26 | B2: 90
A3: 598-A37 | B3: 40
A4: N-598-A56 | B4: 90
A7: 598-S26 | B7: 21
A8: 598-S26plus | B8: 10
A9: 598-S26ultra | B9: 60
A11: 598-E14 | B11: 65
A13: N-598-i11 | B13: 70
A14: N-598-i12 | B14: 70
A15: N-598-i13 | B15: 150
A16: N-598-i14 | B16: 120
... A27: N-598-PocoM8pro-5G | B27: 60

Sheet 599
A2: 599-A9plus-blk | B2: 60 | C2: X40
A3: 599-A9-blk | B3: 70 | C3: X50
A4: 599-A11plus-blk | B4: 180 | C4: x40 | D4: Apuntar lo que vendimos
A5: 599-RmPad2
A7: PANTACO
A8: 599-A11plus-blk | B8: 520 | C8: 30 CAJAS
A9: 599-A9plus-blk | B9: 320 | C9: 8 CAJAS
A10: 599-A9-blk | B10: 300 | C10: 6 CAJAS

Sheet 601
A2: N-601-A11 | B2: 900 | C2: x100
A3: 601-A11plus | B3: 610 | C3: x70
A4: 601-A9plus | B4: 765 | C4: X70
A7: PANTACO
A8: 601-A11 | B8: 7400 | C8: 74
A9: 601-A11plus | B9: 5180 | C9: 74
A10: 601-iPad10 | B10: 3150 | C10: 45

Sheet 602
A3: 602-iPad10-red | B3: 44
A7: 602-A11-red | B7: 70
A8: 602-A11-blue | B8: 40
A9: 602-A11plus-blk | B9: 70
A10: 602-A11plus-pink | B10: 70
A11: 602-A11plus-red | B11: 120
A12: 602-A11plus-blue | B12: 110

Sheet 603
A1: 603-iPad10-red | B1: 170
A2: 603-iPad10-blue | B2: 76
A3: 603-iPad10-purple | B3: 290
A6: 603-A11-blk | B6: 888
A7: 603-A11-red | B7: 420
A8: 603-A11-purple | B8: 710
A9: 603-A11-navy | B9: 280
A11: 603-A11plus-blk | B11: 150
A12: 603-A11plus-purple | B12: 240
A13: 603-A11plus-navy | B13: 50
A15: 603-A9-blk | B15: 30
A17: 603-A9plus-blk | B17: 10 | C17: checar si reetiquetar
A18: 603-A9plus-blue | B18: 150 | C18: tuve que reetiquetar hay que checarlas cada vez
A19: 603-A9plus-red | B19: 160 | C19: checar si reetiquetar

Sheet 604
A2: C-604-i11pro-pink | B2: 42
A3: 604-i11promax-pink | B3: 10
A4: 604-i11promax-purple | B4: 28
A6: 604-i14pro-transparent-C | B6: 8
A7: 604-i15-transparent | B7: 4
A10: 604-i16pro-blk-C | B10: 23
A11: 604-i16pro-purple-C | B11: 69
A12: C-604-i16pro-pink | B12: 59
A13: 604-i16pro-transparent-C | B13: 55
A15: C-604-i16promax-blk | B15: 26
A17: C-604-i17promax-pink | B17: 41
A18: C-604-i17pro-purple | B18: 30
... A23: C-604-iAir-pink | B23: 30

Sheet 606
A1: 606-i11promax | B1: 10
A2: 606-i13promax | B2: 10
A3: 606-i14promax | B3: 40
A4: 606-i15promax | B4: 40
A5: 606-i16 | B5: 20
A6: 606-i16plus | B6: 20
A7: 606-i16pro | B7: 20
A8: 606-i16promax | B8: 40

Sheet 607
A1: 607-A25 | B1: 21
A8: 607-S24 | B8: 18
A11: 607-S25 | B11: 90
A12: 607-S25plus | B12: 30
A13: 607-S25ultra | B13: 16

Sheet 613
A1: 613-A11plus-blk | B1: 454
A2: 613-A11plus-purple | B2: 224
A3: 613-A11plus-pink | B3: 75
A4: 613-A11plus-navy | B4: 195
A5: 613-A11plus-magenta | B5: 172
A7: 613-A11-blk | B7: 817
A8: 613-A11-purple | B8: 502
A9: 613-A11-navy | B9: 340
A10: 613-A11-magenta | B10: 260
A11: 613-A11-red | B11: 343
A13: 613-RmPad-2-red | B13: 82
A14: 613-RmPad-2-blk | B14: 419
... A16: 613-RmPad-2-navy | B16: 130

Sheet 616
A7: 616-i14promax-blk | B7: 20
A8: 616-i15plus-blk | B8: 10
A9: 616-i15pro-blk | B9: 10
A10: 616-i15pro-blue | B10: 30
A11: 616-i15pro-pink | B11: 30
A12: 616-i15promax-pink | B12: 20
A14: 616-i16-blue | B14: 10
A15: 616-i16-pink | B15: 10
A16: 616-i16e-blk | B16: 40
A17: 616-i16e-pink | B17: 10
A18: 616-i16plus-blk | B18: 20
A19: 616-i16plus-blue | B19: 10
... A25: 616-i16promax-pink | B25: 10

Sheet 617
A5: 617-iPad10-blk | B5: 55
A6: 617-iPad10-red | B6: 25
A7: 617-iPad10-blue | B7: 10

Sheet 620
A2: 620-A9plus | B2: 100
A5: 620-iPad10 | B5: 560 | C5: x70

Sheet 621
A2: C-621-i11-purple | B2: 30
A3: 621-i11promax-purple | B3: 10
A4: 621-i12-transparent | B4: 10
A5: 621-i12promax-blk | B5: 10
A7: C-621-i13-transparent | B7: 10
A9: 621-i13promax-blk | B9: 50
A10: 621-i13promax-purple | B10: 8
A11: 621-i14-transparent | B11: 10
A13: 621-i14-pink | B13: 33
A16: 621-i15plus-purple | B16: 55
A17: 621-i15pro-purple | B17: 74
A18: 621-i15pro-pink | B18: 45
... A53: C-621-iAir-pink | B53: 80

Sheet 628
A1: 628-i16plus | B1: 66
A3: 628-i16promax | B3: 130
A4: 628-i16e | B4: 72
A5: 628-i17air | B5: 158

Sheet 639
A3: 639-i15pro-purple | B3: 10
A5: 639-i16pro-blk | B5: 20
A6: 639-i16pro-purple | B6: 10
A8: 639-i17-pink | B8: 70
A9: 639-i17pro-blk | B9: 70
A10: 639-i17pro-pink | B10: 10
A11: 639-i17pro-purple | B11: 70
A12: 639-i17promax-pink | B12: 20
A13: 639-i17promax-purple | B13: 30
A14: 639-iAir-blk | B14: 90
A15: 639-iAir-pink | B15: 40
A16: 639-iAir-purple | B16: 40

Sheet 641
A1: 641-i11 | B1: 140
A2: 641-i12 | B2: 70
A3: 641-i12promax | B3: 30
A4: 641-i13 | B4: 340
A5: 641-i13promax | B5: 110
A6: 641-i14 | B6: 300
A7: 641-i14plus | B7: 80
A8: 641-i14pro | B8: 180
A9: 641-i14promax | B9: 260
A10: 641-i15 | B10: 160
A11: 641-i15plus | B11: 130
A12: 641-i15pro | B12: 170
... A26: 641-ixsmax | B26: 30

Sheet 642
A1: 642-A06-blk | B1: 20
A3: 642-A06-red | B3: 17
A7: 642-A16-red | B7: 10
A8: 642-A25-blk | B8: 10
A9: 642-A26-blk | B9: 30
A10: 642-A26-navy | B10: 20
A11: 642-A26-red | B11: 20
A13: 642-A36-blk | B13: 10
A14: 642-A36-navy | B14: 20
A15: 642-A36-red | B15: 20
A19: 642-S23fe-red | B19: 20
A20: 642-S24-blk | B20: 50
... A34: 642-S25plus-red | B34: 30

Sheet 643
A10: 643-i17pro-blk | B10: 160
A11: 643-i17pro-blue | B11: 120
A12: 643-i17pro-purple | B12: 100
A13: 643-i17promax-blk | B13: 110
A14: 643-i17promax-blue | B14: 80
A15: 643-i17promax-purple | B15: 60
A16: 643-iAir-blk | B16: 180
A17: 643-iAir-blue | B17: 70
A18: 643-iAir-purple | B18: 70

Sheet 644
A1: 644-i11-blk | B1: 50
A2: 644-i11-navy | B2: 80
A3: 644-i12-blk | B3: 110
A4: 644-i12-blue | B4: 80
A5: 644-i12promax-blk | B5: 30
A6: 644-i13-blk | B6: 140
A7: 644-i13-pink | B7: 70
A8: 644-i13promax-blk | B8: 30
A9: 644-i14-blk | B9: 70
A11: 644-i14-purple | B11: 30
A12: 644-i14pro-blk | B12: 70
A13: 644-i14promax-blue | B13: 30
... A33: 644-iAir-purple | B33: 30

Sheet 645
A2: 645-i15plus-purple | B2: 10
A4: 645-i15pro-blue | B4: 30
A5: 645-i15pro-pink | B5: 20
A6: 645-i15pro-purple | B6: 20
A7: 645-i15promax-purple | B7: 10
A9: 645-i16plus-blk | B9: 20
A10: 645-i16plus-blue | B10: 20
A11: 645-i16plus-pink | B11: 10
A12: 645-i16plus-purple | B12: 30
A14: 645-i16pro-blue | B14: 20
A15: 645-i16pro-pink | B15: 10
A16: 645-i16pro-purple | B16: 20

Sheet 646
A1: 646-i11promax-blk | B1: 10
A2: 646-i11promax-purple | B2: 20
A4: 646-i12-pink | B4: 10
A7: 646-i12promax-purple | B7: 20
A8: 646-i13promax-blk | B8: 10
A9: 646-i13promax-purple | B9: 30
A15: 646-i15-purple | B15: 10
A16: 646-i15plus-blk | B16: 20
A17: 646-i15plus-purple | B17: 10
A19: 646-i15pro-navy | B19: 20
A20: 646-i15pro-pink | B20: 30
A21: 646-i15pro-purple | B21: 30
... A36: 646-i16promax-purple | B36: 20

Sheet 647
A2: 647-i11pro | B2: 16
A4: 647-i12 | B4: 44
A5: 647-i12pro | B5: 16
A8: 647-i13pro | B8: 13
A14: 647-i16e | B14: 50
A15: 647-iAir | B15: 57
A16: 647-i17 | B16: 92
A17: 647-i17pro | B17: 25
A18: 647-i17promax | B18: 50

Sheet 648
A1: 648-A05 | B1: 30
A2: 648-A06 | B2: 80
A3: 648-A07 | B3: 170
A4: 648-A15 | B4: 10
A5: 648-A16 | B5: 50
A6: 648-A17 | B6: 110
A7: 648-A22-5G | B7: 40
A8: 648-A25 | B8: 40
A9: 648-A26 | B9: 90
A10: 648-A32 | B10: 30
A11: 648-A35 | B11: 30
A12: 648-A36 | B12: 60
... A39: 648-S26ultra | B39: 189

Sheet 650
A1: 650-S26ultra | B1: 130
A2: CH-650-i11 | B2: 160
A3: CH-650-i12 | B3: 80
A4: CH-650-i13 | B4: 340
A5: CH-650-i13pro | B5: 30
A6: CH-650-i13promax | B6: 30
A7: CH-650-i14 | B7: 190
A8: CH-650-i14plus | B8: 30
A9: CH-650-i14pro | B9: 70
A10: CH-650-i14promax | B10: 70
A12: CH-650-i15plus | B12: 130
A13: CH-650-i15pro | B13: 80
... A24: CH-650-ise | B24: 70

Sheet 651
A2: 651-ix | B2: 10
A9: 651-i16plus | B9: 20
A13: 651-iAir | B13: 80
A16: 651-i17 | B16: 70

Sheet 652
A16: 652-i17 | B16: 20
A17: 652-i17pro | B17: 20
A19: 652-iAir | B19: 70

Sheet 653
A7: 653-S25 | B7: 20
A8: 653-S25plus | B8: 10
A10: 653-S25fe | B10: 70
A11: 653-S26 | B11: 80
A12: 653-S26plus | B12: 30
A18: 653-i17 | B18: 80
A19: 653-i17air | B19: 80

Sheet 654

Sheet 655
A4: 655-A11-pink | B4: 306 | C4: x60
A5: 655-A11-blue | B5: 196 | C5: x60

Sheet 656
A2: 656-A9plus-navy | B2: 212 | C2: x47
A3: 656-A9plus-red | B3: 74 | C3: x47
A4: 656-A9plus-purple | B4: 215 | C4: x47
A5: 656-A9-red | B5: 15
A6: 656-A9-purple | B6: 13
A7: 656-A9-blk | B7: 59
A8: 656-A9-navy | B8: 50
A10: 656-A11-navy | B10: 35
A11: 656-A11-purple | B11: 97
A13: 656-A11-red | B13: 65
A15: 656-A11plus-red | B15: 55 | C15: X47
A16: 656-A11plus-purple | B16: 45 | C16: X47
A21: 656-iPad10-purple | B21: 340 | C21: x45

Sheet 657
A3: 657-iPad10-purple | B3: 165 | C3: x30
A4: 657-iPad10-red | B4: 74 | C4: x30
A6: 657-A11-blk | B6: 61 | C6: x50
A7: 657-A11-navy | B7: 220
A8: 657-A11-red | B8: 70
A9: 657-A11-purple | B9: 170
A11: 657-A11plus-navy | B11: 80 | C11: x30
A12: 657-A11plus-red | B12: 30 | C12: x30
A13: 657-A11plus-purple | B13: 76 | C13: x30

Sheet 658
A1: 658-A9plus-blk | B1: 21
A2: 658-A9plus-red | B2: 37
A8: 658-iPad10-red | B8: 75 | C8: x30
A11: 658-A11-navy | B11: 140 | C11: x50
A12: 658-A11-pink | B12: 120 | C12: x50
A13: 658-A11-red | B13: 74 | C13: x50
A16: 658-A11plus-navy | B16: 160 | C16: x30
A17: 658-A11plus-pink | B17: 170
A18: 658-A11plus-red | B18: 50
A19: 658-A11plus-blk | B19: 60
A21: 658-A9-red | B21: 28

Sheet 659
A2: 659-i12-pink | B2: 20
A3: 659-i13promax-pink | B3: 20
A4: 659-i14-blk | B4: 10
A6: 659-i14-pink | B6: 20
A7: 659-i14-purple | B7: 20
A8: 659-i14pro-pink | B8: 20
A9: 659-i14promax-pink | B9: 20
A10: 659-i15-blk | B10: 20
A11: 659-i15-purple | B11: 30
A12: 659-i15pro-blk | B12: 20
A13: 659-i15pro-pink | B13: 40
A15: 659-i15promax-blue | B15: 10
... A27: 659-i16promax-purple | B27: 20

Sheet 662
A1: 662-A07-blk | B1: 140
A2: 662-A07-cream | B2: 30
A3: 662-A07-fuchsia | B3: 80
A4: 662-A07-green | B4: 70
A5: 662-A16-blk | B5: 20
A6: 662-A16-cream | B6: 40
A7: 662-A16-fuchsia | B7: 40
A8: 662-A16-green | B8: 60
A9: 662-A17-blk | B9: 140
A11: 662-A17-fuchsia | B11: 80
A12: 662-A17-green | B12: 160
A13: 662-A26-fuchsia | B13: 10
... A126: 662-Rmn15pro+5G-green | B126: 40

Sheet 663
A5: 663-i15-blk | B5: 30
A7: 663-i16-blk | B7: 30
A8: 663-i16plus-blk | B8: 20
A9: 663-i16pro-blk | B9: 50
A10: 663-i16e-blk | B10: 30
A11: 663-i16promax-blk | B11: 40
A12: 663-i17-blk | B12: 60
A13: 663-i17pro-blk | B13: 80
A14: 663-i17promax-blk | B14: 60
A15: 663-iAir-blk | B15: 40

Sheet 664
A1: 664-i11promax-pink | B1: 30
A4: 664-i14pro-pink | B4: 10
A5: 664-i14promax-pink | B5: 20
A8: 664-i15plus-blk | B8: 10
A9: 664-i15plus-pink | B9: 10
A10: 664-i15pro-pink | B10: 30
A12: 664-i15promax-lilac | B12: 10
A13: 664-i15promax-pink | B13: 20
A15: 664-i16plus-blk | B15: 20
A16: 664-i16plus-blue | B16: 20
A17: 664-i16plus-lilac | B17: 30
A18: 664-i16plus-pink | B18: 9
... A25: 664-i16promax-pink | B25: 30

Sheet 665
A5: 665-PocoX6pro-blue | B5: 10
A6: 665-PocoX6pro-blk | B6: 30
A7: 665-PocoX6pro-fuchsia | B7: 10
A8: 665-PocoX6pro-purple | B8: 20
A9: 665-PocoX6pro-cream | B9: 20
A10: 665-PocoX6pro-pink | B10: 10
A12: 665-A26-cream | B12: 10
A13: 665-S23fe-blk | B13: 20
A14: 665-S23fe-pink | B14: 10
A15: 665-S24-blk | B15: 40
A16: 665-S24-purple | B16: 5
A17: 665-S24-pink | B17: 15
... A31: 665-S25plus-pink | B31: 30

Sheet 666
A1: 666-G35-blk | B1: 40
A5: 666-G55-blk | B5: 20
A8: 666-PocoX6pro-blk | B8: 30
A9: 666-PocoX6pro-fuchsia | B9: 20
A10: 666-PocoX6pro-mint | B10: 20
A11: 666-PocoX6pro-lilac | B11: 20
A12: 666-PocoX7pro-fuchsia | B12: 10
A15: 666-A26-blk | B15: 20
A16: 666-A35-blk | B16: 40
A18: 666-S23fe-blk | B18: 30
A19: 666-S24-blk | B19: 100
A20: 666-S24-fuchsia | B20: 30
... A38: 666-S25ultra-fuchsia | B38: 10

Sheet 667
A6: 667-S24-purple | B6: 20
A7: 667-S24fe-purple | B7: 10
A8: 667-S24fe-pink | B8: 30
A9: 667-S24plus-purple | B9: 10
A11: 667-S25-blk | B11: 10
A12: 667-S25-blue | B12: 30
A13: 667-S25-purple | B13: 40
A14: 667-S25-pink | B14: 40
A15: 667-S25plus-blk | B15: 20
A16: 667-S25plus-purple | B16: 30
A17: 667-S25ultra-pink | B17: 10

Sheet 669
A1: 669-G04/G24-blk | B1: 10
A2: 669-G04/G24-pink | B2: 10
A3: 669-G04/G24-white | B3: 30
A4: 669-G24power-blk | B4: 40
A5: 669-G24power-pink | B5: 40
A6: 669-G24power-purple | B6: 20
A7: 669-G24power-white | B7: 40
A8: 669-G35-blk | B8: 30
A9: 669-G35-pink | B9: 30
A10: 669-G35-purple | B10: 40
A11: 669-G35-white | B11: 30
A12: 669-G54-blk | B12: 30
... A74: 669-Rm14C/C75-white | B74: 30

Sheet 670
A1: 670-PocoM7pro-blue | B1: 30
A2: 670-PocoM7pro-pink | B2: 30
A3: 670-PocoM7pro-purple | B3: 20
A4: 670-PocoM7pro-red | B4: 40
A5: 670-PocoX6pro-pink | B5: 20
A6: 670-PocoX6pro-red | B6: 20
A7: 670-PocoX7pro-pink | B7: 20
A8: 670-Rm14c/C75-blue | B8: 10
A9: 670-Rm14c/C75-pink | B9: 20
A10: 670-Rm14c/C75-red | B10: 40
A13: 670-E14-pink | B13: 20
A14: 670-E14-red | B14: 20
... A37: 670-S26plus-purple | B37: 30

Sheet 671
A1: 671-i11-white | B1: 16
A2: 671-i12-purple | B2: 7
A3: 671-i13promax-purple | B3: 12
A4: 671-i14-purple | B4: 19
A5: 671-i14plus-blk | B5: 7
A6: 671-i14plus-purple | B6: 22
A8: 671-i14pro-purple | B8: 8
A9: 671-i14promax-purple | B9: 10
A10: 671-i15-purple | B10: 41
A11: 671-i15plus-blk | B11: 20
A12: 671-i15plus-purple | B12: 30
A13: 671-i15pro-blk | B13: 11
... A30: 671-i16promax-purple | B30: 13

Sheet 674
A1: 674-A9plus-blk | B1: 65
A2: 674-A9plus-fuchsia | B2: 85
A3: 674-A9plus-navy | B3: 15
A5: 674-iPad10-purple | B5: 160
A7: 674-iPad10-fuchsia | B7: 180
A9: 674-A11plus-blk | B9: 100 | C9: x50
A10: 674-A11plus-fuchsia | B10: 180
A11: 674-A11plus-purple | B11: 160
A13: 674-A11-blk | B13: 50 | C13: x60
A14: 674-A11-fuchsia | B14: 140
A15: 674-A11-purple | B15: 180

Sheet 675
A9: N-675-A35-navy | B9: 100
A10: N-675-A35-blk | B10: 30
A12: N-675-A35-purple | B12: 61
A20: N-675-S23fe-blk | B20: 27
A21: N-675-S24-blk | B21: 31
A22: N-675-S24plus-blk | B22: 5
A23: N-675-S24plus-pink | B23: 31
A25: N-675-S25-blk | B25: 26
A27: N-675-S25-purple | B27: 16
A28: N-675-S25-pink | B28: 20
A29: N-675-S25plus-blk | B29: 17
A30: N-675-S25plus-pink | B30: 29
... A33: N-675-S25fe-pink | B33: 10

Sheet 676
A4: 676-i11-purple | B4: 30
A5: 676-i11promax-navy | B5: 20
A6: 676-i11promax-purple | B6: 30
A8: 676-i12-purple | B8: 30
A9: 676-i13-purple | B9: 10
A10: 676-i13promax-navy | B10: 20
A11: 676-i13promax-purple | B11: 20
A12: 676-i14-blk | B12: 20
A13: 676-i14-navy | B13: 30
A14: 676-i14-purple | B14: 30
A15: 676-i14plus-navy | B15: 30
A16: 676-i14plus-purple | B16: 40
... A45: 676-i16e-purple | B45: 30

Sheet 678
A1: 678-A07-blk | B1: 150
A2: 678-A07-navy | B2: 50
A3: 678-A07-purple | B3: 100
A4: 678-A07-red | B4: 50
A5: 678-A16-blk | B5: 80
A6: 678-A17-blk | B6: 150
A7: 678-A17-navy | B7: 50
A8: 678-A17-purple | B8: 100
A9: 678-A17-red | B9: 50
A10: 678-A26-blk | B10: 30
A11: 678-A26-navy | B11: 10
A12: 678-A26-purple | B12: 10
... A158: 678-Rmn15pro+5G-red | B158: 40

Sheet 679
A2: 679-i13-navy | B2: 30
A6: 679-i14-navy | B6: 40
A7: 679-i14plus-blk | B7: 10
A8: 679-i14plus-navy | B8: 20
A9: 679-i14promax-navy | B9: 20
A13: 679-i15pro-navy | B13: 10
A15: 679-i15plus-blk | B15: 30
A16: 679-i15plus-navy | B16: 30
A19: 679-i16-navy | B19: 10
A20: 679-i16plus-blk | B20: 10
A21: 679-i16plus-navy | B21: 30
A22: 679-i16pro-navy | B22: 20
... A32: 679-iAir-navy | B32: 30

Sheet 680
A1: 680-i11promax-navy | B1: 30
A2: 680-i11promax-purple | B2: 20
A3: 680-i13promax-purple | B3: 40
A4: 680-i14-pink | B4: 20
A5: 680-i14-purple | B5: 10
A7: 680-i14plus-purple | B7: 20
A9: 680-i14pro-purple | B9: 20
A10: 680-i15-pink | B10: 10
A11: 680-i15-purple | B11: 20
A12: 680-i15-red | B12: 20
A13: 680-i15plus-navy | B13: 20
A14: 680-i15plus-purple | B14: 30
... A32: 680-i16promax-purple | B32: 30

Sheet 681
A2: 681-A9plus-red | B2: 10

Sheet 682
A1: 682-A9-blk | B1: 25 | C1: tirar
A2: 682-A11-blk | B2: 30

Sheet 683
A1: 683-i11-navy | B1: 10
A2: 683-i11promax-blk | B2: 20
A3: 683-i11promax-purple | B3: 30
A4: 683-i13promax-blk | B4: 20
A5: 683-i13promax-purple | B5: 20
A6: 683-i14-blk | B6: 39
A7: 683-i14-purple | B7: 10
A8: 683-i14plus-purple | B8: 30
A9: 683-i14pro-blk | B9: 10
A10: 683-i14pro-purple | B10: 20
A11: 683-i14promax-blk | B11: 20
A13: 683-i15-purple | B13: 20
... A32: 683-iAir-blk | B32: 40

Sheet 684
A1: 684-ise-purple | B1: 30
A2: 684-i11-pink | B2: 30
A3: 684-i11-purple | B3: 10
A4: 684-i11promax-purple | B4: 30
A5: 684-i12-purple | B5: 20
A6: 684-i13-pink | B6: 10
A7: 684-i13-purple | B7: 20
A8: 684-i13promax-purple | B8: 30
A9: 684-i14-pink | B9: 30
A10: 684-i14-purple | B10: 20
A11: 684-i14plus-purple | B11: 40
A12: 684-i14pro-purple | B12: 30
... A29: 684-i16promax-purple | B29: 30

Sheet 686
A1: 686-A9plus-blk | B1: 130 | C1: X40
A2: 686-A9plus-navy | B2: 70 | C2: X40
A3: 686-A9plus-purple | B3: 80 | C3: X40
A4: 686-A9plus-pink | B4: 120 | C4: X40
A8: N-686-iPad11-purple | B8: 180
A12: 686-A11-blk | B12: 140 | C12: x40 | D12: VAMOS A HACER LISTADO NUEVO
A13: 686-A11-navy | B13: 20 | D13: VAMOS A HACER LISTADO NUEVO
A14: 686-A11-purple | B14: 140 | D14: VAMOS A HACER LISTADO NUEVO
A15: 686-A11-pink | B15: 200 | D15: VAMOS A HACER LISTADO NUEVO
A16: 686-A11-grey | B16: 20 | D16: VAMOS A HACER LISTADO NUEVO
A18: 686-A11plus-blk | B18: 230 | C18: x30 | D18: VAMOS A HACER LISTADO NUEVO
A19: 686-A11plus-navy | B19: 90 | D19: VAMOS A HACER LISTADO NUEVO
A20: 686-A11plus-purple | B20: 150 | D20: VAMOS A HACER LISTADO NUEVO
A21: 686-A11plus-pink | B21: 220 | D21: VAMOS A HACER LISTADO NUEVO
A22: 686-A11plus-grey | B22: 30 | D22: VAMOS A HACER LISTADO NUEVO

Sheet 689
A1: 689-iPad10-blk | B1: 80
A2: 689-iPad10-blue | B2: 20
A3: 689-iPad10-pink | B3: 10

Sheet 703
A7: 703-S25plus | B7: 20
A9: 703-S26 | B9: 70
A10: 703-S26plus | B10: 28

Sheet 714
A1: 714-G05 | B1: 80
A2: 714-G17 | B2: 80
A5: 714-G86 | B5: 30
A6: 714-G86power | B6: 160
A7: 714-E15 | B7: 100
A15: 714-S25 | B15: 60
A16: 714-S25fe | B16: 70
A17: 714-S26 | B17: 138
A18: 714-S26plus | B18: 70
A21: 714-Rmn14s | B21: 60
A22: 714-Rmn15-5G | B22: 90
A23: 714-RmA5 | B23: 40

Sheet 716
A1: 716-A11 | B1: 1060 | C1: X80
A2: 716-A11plus | B2: 1495 | C2: X55

Sheet 718
A1: 718-iPad11-blk | B1: 90 | C1: x50
A4: 718-iPad11-red | B4: 30
A6: 718-A11plus-blk | B6: 230
A7: 718-A11plus-purple | B7: 10
A9: 718-A11plus-pink | B9: 40
A10: 718-A11plus-red | B10: 50
A12: 718-A11-blk | B12: 120
A14: 718-A11-pink | B14: 50

Sheet 721
A3: 721-Rmn14-5G-pink | B3: 20
A4: 721-Rmn14-5G-purple | B4: 17
A5: 721-Rmn14pro-4G-pink | B5: 17
A8: 721-Rm13x-purple | B8: 9
A13: 721-Rmn14s-pink | B13: 31

Sheet 722
A2: 722-G06-purple | B2: 20
A3: 722-G06-blk | B3: 10
A4: 722-G15-pink | B4: 20
A5: 722-G15-purple | B5: 20
A6: 722-G55-pink | B6: 40
A7: 722-G55-purple | B7: 40
A8: 722-G56-pink | B8: 40
A9: 722-G56-purple | B9: 40
A10: 722-G56-blk | B10: 40
A11: 722-G86-pink | B11: 30
A12: 722-G86-purple | B12: 30
A13: 722-G86-blk | B13: 40
... A67: 722-Rm15C/C85-purple | B67: 20

Sheet 723
A1: 723-A11-blk | B1: 50
A3: 723-iPad11-blk | B3: 100
A4: 723-iPad11-navy | B4: 50
A5: 723-iPad11-red | B5: 50
A6: 723-iPad11-purple | B6: 30

Sheet 728
A1: 728-A07-blk | B1: 100
A2: 728-A07-navy | B2: 69
A4: 728-A07-red | B4: 20
A5: 728-A17-blk | B5: 100
A6: 728-A17-navy | B6: 80
A7: 728-A17-pink | B7: 20
A9: 728-A56-blk | B9: 120
A10: 728-A56-pink | B10: 110
A11: 728-A57-blk | B11: 120
A12: 728-A57-navy | B12: 70
A13: 728-A57-pink | B13: 50
A14: 728-A57-red | B14: 30
... A71: 728-Rmn15pro+5G-pink | B71: 30

Sheet 729
A6: 729-S24 | B6: 30
A11: 729-S26 | B11: 70
A20: 729-E15 | B20: 20

Sheet 730
A1: 730-PocoC71-blue | B1: 29
A2: 730-PocoC71-pink | B2: 40
A3: 730-PocoC71-fuchsia | B3: 40
A4: 730-PocoC71-purple | B4: 39
A5: 730-PocoM7-blue | B5: 30
A6: 730-PocoM7-pink | B6: 40
A7: 730-PocoM7-fuchsia | B7: 40
A8: 730-PocoM7-purple | B8: 40
A9: 730-PocoX7pro-blue | B9: 30
A10: 730-PocoX7pro-pink | B10: 40
A11: 730-PocoX7pro-fuchsia | B11: 40
A12: 730-PocoX7pro-purple | B12: 40
... A94: 730-E15-purple | B94: 40

Sheet 735
A1: 735-A07-baby pink | B1: 70
A2: 735-A07-pink | B2: 64
A4: 735-A37-baby pink | B4: 95
A5: 735-A37-pink | B5: 70
A6: 735-A37-purple | B6: 35
A7: 735-G06-baby pink | B7: 88
A8: 735-G06-pink | B8: 73
A9: 735-G06-purple | B9: 34
A10: 735-G56-baby pink | B10: 108
A11: 735-G56-pink | B11: 109
A12: 735-G56-purple | B12: 102
A13: 735-G86-baby pink | B13: 80
... A24: 735-S26ultra-purple | B24: 71

Sheet 739
A1: 739-i11 | B1: 20
A2: 739-i11promax | B2: 20
A3: 739-i12 | B3: 70
A4: 739-i13 | B4: 120
A5: 739-i14 | B5: 20
A6: 739-i15promax | B6: 80
A7: 739-i16 | B7: 60
A9: 739-i17 | B9: 80
A10: 739-i17pro | B10: 20
A11: 739-i17promax | B11: 160
A12: 739-iAir | B12: 30

Sheet 745
A1: 745-iPad11-blk | B1: 120 | C1: x20

Sheet 748
A1: P605
A2: 748-S25ultra | B2: 20
A3: 748-S26 | B3: 30
A4: 748-S26ultra | B4: 30

Sheet 749
A1: P605
A2: 749-iPad11 | B2: 330
A3: 749-A11 | B3: 160
A4: 749-A11plus | B4: 160

Sheet 750
A1: P605
A2: 750-iPad11 | B2: 30
A3: 750-A11 | B3: 60
A4: 750-A11plus | B4: 60

Sheet 754
A1: P605
A2: 754-A07-blk | B2: 30
A3: 754-A07-blue | B3: 50
A4: 754-A07-gold | B4: 50
A5: 754-A17-blk | B5: 40
A6: 754-A17-blue | B6: 50
A7: 754-A17-gold | B7: 50
A8: 754-A37-blk | B8: 50
A9: 754-A37-blue | B9: 50
A10: 754-A37-gold | B10: 50
A11: 754-A57-blk | B11: 40
A12: 754-A57-blue | B12: 50
A13: 754-A57-gold | B13: 50
... A18: 754-S26ultra-blk | B18: 40

Sheet 416
A2: 14009-iPad10-purple | B2: 500
A3: 14009-iPad10-mint | B3: 150
A4: 14009-iPad10-Blue | B4: 50
A6: 14009-iPad10-Green | B6: 50

Sheet RETIRO
A1: 437-A11-blk | B1: 54
A2: 437-A11-purple | B2: 27
A3: 437-A11plus-magenta | B3: 51
A4: 437-A11plus-navy | B4: 36
A5: 437-A11plus-purple | B5: 46
A6: 437-ipad10-blue | B6: 160
A7: 437-ipad10-purple | B7: 206
A8: 437-ipad10-red | B8: 20
A9: 439-E14-pink | B9: 33
A10: 450-A17 | B10: 30
A11: 450-A56 | B11: 42
A12: 450-G24 | B12: 20
... A50: N-675-S25ultra-blk | B50: 25
